<robot name="onshape">
<link name="base_link"></link>
<joint name="base_link_to_base" type="fixed">
<parent link="base_link"/>
<child link="arm_holder" />
<origin rpy="0.0 0 0" xyz="0 0 0"/>
</joint>
<link name="arm_holder">
<collision>
<origin xyz="0 0 0" rpy="0 -0 0" />
<geometry>
<mesh filename="package:///arm_holder_collision.stl"/>
</geometry>
</collision>
<inertial>
<origin xyz="-0.0024604819858035000685 0 0.024278036281569582988" rpy="0 0 0"/>
<mass value="0.038331078295993678551" />
<inertia ixx="2.7090355107728517531e-05" ixy="0"  ixz="1.9166481251966513792e-06" iyy="3.9211392276382927365e-05" iyz="0" izz="1.8997633730809045403e-05" />
</inertial>
<visual><geometry><box size="0 0 0" /></geometry></visual>
</link>

<link name="arm_holder_1">
<inertial>
<origin xyz="0 0 0" rpy="0 0 0" />
<mass value="1e-9" />
<inertia ixx="0" ixy="0" ixz="0" iyy="0" iyz="0" izz="0" />
</inertial>
<visual>
<origin xyz="-8.6736173798840354721e-18 0.015875000000000000222 0.0019049999999999952388" rpy="0 -0 0" />
<geometry>
<mesh filename="package:///arm_holder.stl"/>
</geometry>
<material name="arm_holder_1_visual_material">
<color rgba="0.61568627450980395466 0.81176470588235294379 0.92941176470588238168 1.0"/>
</material>
</visual>
</link>
<joint name="arm_holder_1_fixing" type="fixed">
<origin xyz="0 0 0" rpy="0 -0 0" />
<parent link="arm_holder" />
<child link="arm_holder_1" />
<axis xyz="0 0 1"/>
<limit effort="1" velocity="20" />
<joint_properties friction="0.0"/>
</joint>

<link name="_hs-322hd">
<collision>
<origin xyz="0 0 0" rpy="0 -0 0" />
<geometry>
<mesh filename="package:///_hs-322hd_collision.stl"/>
</geometry>
</collision>
<inertial>
<origin xyz="-0.019787117234778824754 -0.01184625467725158518 -2.4519802017345660083e-09" rpy="0 0 0"/>
<mass value="0.049980665650601885375" />
<inertia ixx="7.0131811608219737849e-06" ixy="-1.5101767013654891429e-07"  ixz="-5.6367497207547697834e-12" iyy="8.3052763995078660925e-06" iyz="4.1885363794419766211e-13" izz="1.2153241500714573236e-05" />
</inertial>
<visual><geometry><box size="0 0 0" /></geometry></visual>
</link>

<link name="_hs-322hd_1">
<inertial>
<origin xyz="0 0 0" rpy="0 0 0" />
<mass value="1e-9" />
<inertia ixx="0" ixy="0" ixz="0" iyy="0" iyz="0" izz="0" />
</inertial>
<visual>
<origin xyz="-0.020000000000000000416 -0.027500000000000000139 -1.6359650383255208305e-09" rpy="1.1112366654875553104e-10 -0 0" />
<geometry>
<mesh filename="package:///_hs-322hd.stl"/>
</geometry>
<material name="_hs-322hd_1_visual_material">
<color rgba="0.2313725490196078538 0.38039215686274507888 0.7058823529411765163 1.0"/>
</material>
</visual>
</link>
<joint name="_hs-322hd_1_fixing" type="fixed">
<origin xyz="0 0 0" rpy="0 -0 0" />
<parent link="_hs-322hd" />
<child link="_hs-322hd_1" />
<axis xyz="0 0 1"/>
<limit effort="1" velocity="20" />
<joint_properties friction="0.0"/>
</joint>

<link name="base_arm_part">
<collision>
<origin xyz="0 0 0" rpy="0 -0 0" />
<geometry>
<mesh filename="package:///base_arm_part_collision.stl"/>
</geometry>
</collision>
<inertial>
<origin xyz="0.0027165783034797698348 -0.12967315748884694626 -0.016202102233383582769" rpy="0 0 0"/>
<mass value="0.035980036837035184183" />
<inertia ixx="0.00028078037166058957084" ixy="-1.5296132519564160664e-06"  ixz="8.3712522197768878629e-09" iyy="1.0821935419361632607e-05" iyz="3.8997682877549268685e-08" izz="0.00027550015347193099321" />
</inertial>
<visual><geometry><box size="0 0 0" /></geometry></visual>
</link>

<link name="base_arm_part_1">
<inertial>
<origin xyz="0 0 0" rpy="0 0 0" />
<mass value="1e-9" />
<inertia ixx="0" ixy="0" ixz="0" iyy="0" iyz="0" izz="0" />
</inertial>
<visual>
<origin xyz="0.012699999999999997749 0.012699999999999968259 0.0036195000000000671081" rpy="1.570796326794896558 1.5707963267948961139 0" />
<geometry>
<mesh filename="package:///base_arm_part.stl"/>
</geometry>
<material name="base_arm_part_1_visual_material">
<color rgba="0.61568627450980395466 0.81176470588235294379 0.92941176470588238168 1.0"/>
</material>
</visual>
</link>
<joint name="base_arm_part_1_fixing" type="fixed">
<origin xyz="0 0 0" rpy="0 -0 0" />
<parent link="base_arm_part" />
<child link="base_arm_part_1" />
<axis xyz="0 0 1"/>
<limit effort="1" velocity="20" />
<joint_properties friction="0.0"/>
</joint>

<link name="part_1">
<collision>
<origin xyz="0 0 0" rpy="0 -0 0" />
<geometry>
<mesh filename="package:///part_1_collision.stl"/>
</geometry>
</collision>
<inertial>
<origin xyz="0.0030652254965877860637 -0.058360607838242463397 0.0090169999999999729534" rpy="0 0 0"/>
<mass value="0.023127123465820405984" />
<inertia ixx="5.6647965796974981934e-05" ixy="3.1153604514067943625e-08"  ixz="6.5125424834559953403e-31" iyy="3.4536765799298176309e-06" iyz="1.0980830174975170504e-34" izz="5.6507798808386089004e-05" />
</inertial>
<visual><geometry><box size="0 0 0" /></geometry></visual>
</link>

<link name="part_1_1">
<inertial>
<origin xyz="0 0 0" rpy="0 0 0" />
<mass value="1e-9" />
<inertia ixx="0" ixy="0" ixz="0" iyy="0" iyz="0" izz="0" />
</inertial>
<visual>
<origin xyz="0.012700000000000696843 0.019914204896853526794 0.019811999999999975464" rpy="1.570796326794896558 1.570796326794896558 0" />
<geometry>
<mesh filename="package:///part_1.stl"/>
</geometry>
<material name="part_1_1_visual_material">
<color rgba="0.61568627450980395466 0.81176470588235294379 0.92941176470588238168 1.0"/>
</material>
</visual>
</link>
<joint name="part_1_1_fixing" type="fixed">
<origin xyz="0 0 0" rpy="0 -0 0" />
<parent link="part_1" />
<child link="part_1_1" />
<axis xyz="0 0 1"/>
<limit effort="1" velocity="20" />
<joint_properties friction="0.0"/>
</joint>

<joint name="second_stage_arm" type="revolute">
<origin xyz="-1.4297916149652589723e-17 -0.26589736000000013805 -0.030797499999999207454" rpy="1.1408386409076440936e-16 8.8940818644187655745e-17 0.0016804094650094574849" />
<parent link="base_arm_part" />
<child link="part_1" />
<axis xyz="0 0 1"/>
<limit effort="1" velocity="20" />
<joint_properties friction="0.0"/>
</joint>

<joint name="base_arm" type="revolute">
<origin xyz="-0.010000000000000997674 0.011600000000000769418 -1.6316198063596397266e-09" rpy="-1.5707963793909751615 1.5686835501809441862 3.1415926009938330843" />
<parent link="_hs-322hd" />
<child link="base_arm_part" />
<axis xyz="0 0 1"/>
<limit effort="1" velocity="20" />
<joint_properties friction="0.0"/>
</joint>

<joint name="servo_link" type="fixed">
<origin xyz="0.022224999999999998229 -6.9388939039072283776e-18 0.025400000000000016315" rpy="-1.570796326794896558 1.5707963267948961139 0" />
<parent link="arm_holder" />
<child link="_hs-322hd" />
<axis xyz="0 0 1"/>
<limit effort="1" velocity="20" />
<joint_properties friction="0.0"/>
</joint>


</robot>
